{
 "cells": [
  {
   "cell_type": "code",
   "execution_count": 11,
   "id": "267d66a5",
   "metadata": {},
   "outputs": [
    {
     "name": "stdout",
     "output_type": "stream",
     "text": [
      "Unexpected exception formatting exception. Falling back to standard exception\n"
     ]
    },
    {
     "name": "stderr",
     "output_type": "stream",
     "text": [
      "Traceback (most recent call last):\n",
      "  File \"C:\\Users\\Himanshu Sharma\\anaconda3\\Lib\\site-packages\\IPython\\core\\formatters.py\", line 223, in catch_format_error\n",
      "    r = method(self, *args, **kwargs)\n",
      "        ^^^^^^^^^^^^^^^^^^^^^^^^^^^^^\n",
      "  File \"C:\\Users\\Himanshu Sharma\\anaconda3\\Lib\\site-packages\\IPython\\core\\formatters.py\", line 344, in __call__\n",
      "    return method()\n",
      "           ^^^^^^^^\n",
      "  File \"C:\\Users\\Himanshu Sharma\\anaconda3\\Lib\\site-packages\\pandas\\core\\frame.py\", line 1136, in _repr_html_\n",
      "  File \"C:\\Users\\Himanshu Sharma\\anaconda3\\Lib\\site-packages\\pandas\\io\\formats\\format.py\", line 1108, in to_html\n",
      "    the leading space to pad between columns.\n",
      "             ^^^^^^^^^^^^^^^^^^^^^^^^^^\n",
      "  File \"C:\\Users\\Himanshu Sharma\\anaconda3\\Lib\\site-packages\\pandas\\io\\formats\\html.py\", line 88, in to_string\n",
      "    lines = self.render()\n",
      "            ^^^^^^^^^^^^^\n",
      "  File \"C:\\Users\\Himanshu Sharma\\anaconda3\\Lib\\site-packages\\pandas\\io\\formats\\html.py\", line 644, in render\n",
      "    super().render()\n",
      "  File \"C:\\Users\\Himanshu Sharma\\anaconda3\\Lib\\site-packages\\pandas\\io\\formats\\html.py\", line 94, in render\n",
      "    self._write_table()\n",
      "  File \"C:\\Users\\Himanshu Sharma\\anaconda3\\Lib\\site-packages\\pandas\\io\\formats\\html.py\", line 267, in _write_table\n",
      "    self._write_header(indent + self.indent_delta)\n",
      "  File \"C:\\Users\\Himanshu Sharma\\anaconda3\\Lib\\site-packages\\pandas\\io\\formats\\html.py\", line 403, in _write_header\n",
      "    self._write_col_header(indent + self.indent_delta)\n",
      "  File \"C:\\Users\\Himanshu Sharma\\anaconda3\\Lib\\site-packages\\pandas\\io\\formats\\html.py\", line 383, in _write_col_header\n",
      "    row.extend(self._get_columns_formatted_values())\n",
      "               ^^^^^^^^^^^^^^^^^^^^^^^^^^^^^^^^^^^^\n",
      "  File \"C:\\Users\\Himanshu Sharma\\anaconda3\\Lib\\site-packages\\pandas\\io\\formats\\html.py\", line 611, in _get_columns_formatted_values\n",
      "    return self.columns._format_flat(include_name=False)\n",
      "           ^^^^^^^^^^^^^^^^^^^^^^^^^\n",
      "AttributeError: 'Index' object has no attribute '_format_flat'\n",
      "\n",
      "During handling of the above exception, another exception occurred:\n",
      "\n",
      "Traceback (most recent call last):\n",
      "  File \"C:\\Users\\Himanshu Sharma\\anaconda3\\Lib\\site-packages\\IPython\\core\\interactiveshell.py\", line 2120, in showtraceback\n",
      "    stb = self.InteractiveTB.structured_traceback(\n",
      "          ^^^^^^^^^^^^^^^^^^^^^^^^^^^^^^^^^^^^^^^^\n",
      "  File \"C:\\Users\\Himanshu Sharma\\anaconda3\\Lib\\site-packages\\IPython\\core\\ultratb.py\", line 1435, in structured_traceback\n",
      "    return FormattedTB.structured_traceback(\n",
      "           ^^^^^^^^^^^^^^^^^^^^^^^^^^^^^^^^^\n",
      "  File \"C:\\Users\\Himanshu Sharma\\anaconda3\\Lib\\site-packages\\IPython\\core\\ultratb.py\", line 1326, in structured_traceback\n",
      "    return VerboseTB.structured_traceback(\n",
      "           ^^^^^^^^^^^^^^^^^^^^^^^^^^^^^^^\n",
      "  File \"C:\\Users\\Himanshu Sharma\\anaconda3\\Lib\\site-packages\\IPython\\core\\ultratb.py\", line 1173, in structured_traceback\n",
      "    formatted_exception = self.format_exception_as_a_whole(etype, evalue, etb, number_of_lines_of_context,\n",
      "                          ^^^^^^^^^^^^^^^^^^^^^^^^^^^^^^^^^^^^^^^^^^^^^^^^^^^^^^^^^^^^^^^^^^^^^^^^^^^^^^^^\n",
      "  File \"C:\\Users\\Himanshu Sharma\\anaconda3\\Lib\\site-packages\\IPython\\core\\ultratb.py\", line 1088, in format_exception_as_a_whole\n",
      "    frames.append(self.format_record(record))\n",
      "                  ^^^^^^^^^^^^^^^^^^^^^^^^^^\n",
      "  File \"C:\\Users\\Himanshu Sharma\\anaconda3\\Lib\\site-packages\\IPython\\core\\ultratb.py\", line 970, in format_record\n",
      "    frame_info.lines, Colors, self.has_colors, lvals\n",
      "    ^^^^^^^^^^^^^^^^\n",
      "  File \"C:\\Users\\Himanshu Sharma\\anaconda3\\Lib\\site-packages\\IPython\\core\\ultratb.py\", line 792, in lines\n",
      "    return self._sd.lines\n",
      "           ^^^^^^^^^^^^^^\n",
      "  File \"C:\\Users\\Himanshu Sharma\\anaconda3\\Lib\\site-packages\\stack_data\\utils.py\", line 145, in cached_property_wrapper\n",
      "    value = obj.__dict__[self.func.__name__] = self.func(obj)\n",
      "                                               ^^^^^^^^^^^^^^\n",
      "  File \"C:\\Users\\Himanshu Sharma\\anaconda3\\Lib\\site-packages\\stack_data\\core.py\", line 698, in lines\n",
      "    pieces = self.included_pieces\n",
      "             ^^^^^^^^^^^^^^^^^^^^\n",
      "  File \"C:\\Users\\Himanshu Sharma\\anaconda3\\Lib\\site-packages\\stack_data\\utils.py\", line 145, in cached_property_wrapper\n",
      "    value = obj.__dict__[self.func.__name__] = self.func(obj)\n",
      "                                               ^^^^^^^^^^^^^^\n",
      "  File \"C:\\Users\\Himanshu Sharma\\anaconda3\\Lib\\site-packages\\stack_data\\core.py\", line 649, in included_pieces\n",
      "    pos = scope_pieces.index(self.executing_piece)\n",
      "                             ^^^^^^^^^^^^^^^^^^^^\n",
      "  File \"C:\\Users\\Himanshu Sharma\\anaconda3\\Lib\\site-packages\\stack_data\\utils.py\", line 145, in cached_property_wrapper\n",
      "    value = obj.__dict__[self.func.__name__] = self.func(obj)\n",
      "                                               ^^^^^^^^^^^^^^\n",
      "  File \"C:\\Users\\Himanshu Sharma\\anaconda3\\Lib\\site-packages\\stack_data\\core.py\", line 628, in executing_piece\n",
      "    return only(\n",
      "           ^^^^^\n",
      "  File \"C:\\Users\\Himanshu Sharma\\anaconda3\\Lib\\site-packages\\executing\\executing.py\", line 164, in only\n",
      "    raise NotOneValueFound('Expected one value, found 0')\n",
      "executing.executing.NotOneValueFound: Expected one value, found 0\n"
     ]
    },
    {
     "data": {
      "text/plain": [
       "   total_bill   tip     sex smoker  day    time  size\n",
       "0       16.99  1.01  Female     No  Sun  Dinner     2\n",
       "1       10.34  1.66    Male     No  Sun  Dinner     3\n",
       "2       21.01  3.50    Male     No  Sun  Dinner     3\n",
       "3       23.68  3.31    Male     No  Sun  Dinner     2\n",
       "4       24.59  3.61  Female     No  Sun  Dinner     4"
      ]
     },
     "execution_count": 11,
     "metadata": {},
     "output_type": "execute_result"
    }
   ],
   "source": [
    "import seaborn as sns\n",
    "df = sns.load_dataset('tips')\n",
    "df.head()"
   ]
  },
  {
   "cell_type": "code",
   "execution_count": null,
   "id": "6bc56b25",
   "metadata": {},
   "outputs": [],
   "source": []
  },
  {
   "cell_type": "code",
   "execution_count": 12,
   "id": "4942e058",
   "metadata": {},
   "outputs": [
    {
     "ename": "ImportError",
     "evalue": "cannot import name 'DataError' from 'pandas.core.base' (C:\\Users\\Himanshu Sharma\\anaconda3\\Lib\\site-packages\\pandas\\core\\base.py)",
     "output_type": "error",
     "traceback": [
      "\u001b[1;31m---------------------------------------------------------------------------\u001b[0m",
      "\u001b[1;31mImportError\u001b[0m                               Traceback (most recent call last)",
      "Cell \u001b[1;32mIn[12], line 1\u001b[0m\n\u001b[1;32m----> 1\u001b[0m \u001b[38;5;28;01mfrom\u001b[39;00m \u001b[38;5;21;01mpandas\u001b[39;00m\u001b[38;5;21;01m.\u001b[39;00m\u001b[38;5;21;01mcore\u001b[39;00m\u001b[38;5;21;01m.\u001b[39;00m\u001b[38;5;21;01mbase\u001b[39;00m \u001b[38;5;28;01mimport\u001b[39;00m DataError\n\u001b[0;32m      2\u001b[0m \u001b[38;5;28;01mfrom\u001b[39;00m \u001b[38;5;21;01mpandas_profiling\u001b[39;00m \u001b[38;5;28;01mimport\u001b[39;00m ProfileReport\n\u001b[0;32m      3\u001b[0m profile\u001b[38;5;241m=\u001b[39mProfileReport(df,explorative\u001b[38;5;241m=\u001b[39m\u001b[38;5;28;01mTrue\u001b[39;00m)\n",
      "\u001b[1;31mImportError\u001b[0m: cannot import name 'DataError' from 'pandas.core.base' (C:\\Users\\Himanshu Sharma\\anaconda3\\Lib\\site-packages\\pandas\\core\\base.py)"
     ]
    }
   ],
   "source": [
    "from pandas.core.base import DataError\n",
    "from pandas_profiling import ProfileReport\n",
    "profile=ProfileReport(df,explorative=True)\n",
    "profile.to_file('output.html')"
   ]
  },
  {
   "cell_type": "code",
   "execution_count": null,
   "id": "88e7cd47",
   "metadata": {},
   "outputs": [],
   "source": []
  }
 ],
 "metadata": {
  "kernelspec": {
   "display_name": "Python 3 (ipykernel)",
   "language": "python",
   "name": "python3"
  },
  "language_info": {
   "codemirror_mode": {
    "name": "ipython",
    "version": 3
   },
   "file_extension": ".py",
   "mimetype": "text/x-python",
   "name": "python",
   "nbconvert_exporter": "python",
   "pygments_lexer": "ipython3",
   "version": "3.11.5"
  }
 },
 "nbformat": 4,
 "nbformat_minor": 5
}
